Workbook
Name LongPeriod: '[1]IMPORT DATA'!$D$16
Name Query_List: #REF!
Name Referred: LOOKUPS!$C$2:$C$9
Name Report_Requested: LOOKUPS!$D$2:$D$8
Name Workbook_list: #REF!
Name Wtg_Att_Mgr_Dec: LOOKUPS!$E$2:$E$12
Name Wtg_Referral_Dec: LOOKUPS!$F$2:$F$13

Sheet MASTER
A1: Incident Number | B1: Incident Date | C1: Headcode | D1: Train | E1: Incident Location | F1: Primary Mins Sum | G1: Total Mins | H1: Train Accepted | I1: Trust Mgr | J1: Root Cause | K1: Bugle Status | L1: Report Requested From/Delay Attributed To: | M1: Date Report Requested/Referred or Delay Closed Out | N1: TIN | O1: EFC (if Required) In Progress? | P1: PHRD? | Q1: PHRD Number | R1: PIP/MOD Recommended? | S1: Delay Mins | T1: Lag_Delay_1 | U1: Lag_Delay_2 | V1: Rolling_3_Delay_Avg | W1: Predicted Delay | X1: Error | Y1: Absolute Error
A2: 179509 | B2: 46059 | C2: 1A30 | D2: 17:40 LEEDS to KINGS X | E2: LEEDS | F2: 0 | G2: 0 | H2: 43532 | I2: MHB1 | J2: MN | K2: Accepted | N2: =IF(L2="Availability", 0, IF(AND(#REF!="Y", OR(F2>2,#REF!> 0)), 1, 0)) -> #REF! | S2: =_xlfn.XLOOKUP(E2,DelayData!C:C,DelayData!E:E,"0") -> 0 | T2: 0 | U2: 0 | V2: =IF(COUNT(S2:S4)<3,"",AVERAGE(S2:S4)) -> 0 | W2: =0.5*T2 + 0.3*U2 + 0.2*V2 -> 0 | X2: =S2 - W2 -> 0 | Y2: =ABS(S2 - W2) -> 0
A3: 179324 | B3: 46059 | C3: 1D20 | D3: 15:10 London Kings Cross - Leeds | E3: KNGXBEL | F3: 5 | G3: 5 | I3: MHBA | K3: New | N3: =IF(L3="Availability", 0, IF(AND(#REF!="Y", OR(F3>2,#REF!> 0)), 1, 0)) -> #REF! | S3: =_xlfn.XLOOKUP(E3,DelayData!C:C,DelayData!E:E,"0") -> 0 | T3: =S2 -> 0 | U3: 0 | V3: =IF(COUNT(S3:S5)<3,"",AVERAGE(S3:S5)) -> 0 | W3: =0.5*T3 + 0.3*U3 + 0.2*V3 -> 0 | X3: =S3 - W3 -> 0 | Y3: =ABS(S3 - W3) -> 0
A4: 178432 | B4: 46059 | C4: 1E03 | D4: 06:30 EDINBURGH to KINGS X | E4: NCL KEBGSJN | F4: 2 | G4: 2 | H4: 43896 | I4: MHB2 | K4: New | N4: =IF(L4="Availability", 0, IF(AND(#REF!="Y", OR(F4>2,#REF!> 0)), 1, 0)) -> #REF! | S4: =_xlfn.XLOOKUP(E4,DelayData!C:C,DelayData!E:E,"0") -> 0 | T4: =S3 -> 0 | U4: =S2 -> 0 | V4: =IF(COUNT(S4:S6)<3,"",AVERAGE(S4:S6)) -> 0 | W4: =0.5*T4 + 0.3*U4 + 0.2*V4 -> 0 | X4: =S4 - W4 -> 0 | Y4: =ABS(S4 - W4) -> 0
A5: 177745 | B5: 46059 | C5: 1E10 | D5: 10:00 EDINBURGH to KINGS X | E5: EDB | F5: 0 | G5: 5 | H5: 43852 | I5: MHB2 | J5: MS | K5: Accepted | N5: =IF(L5="Availability", 0, IF(AND(#REF!="Y", OR(F5>2,#REF!> 0)), 1, 0)) -> #REF! | S5: =_xlfn.XLOOKUP(E5,DelayData!C:C,DelayData!E:E,"0") -> 0 | T5: =S4 -> 0 | U5: =S3 -> 0 | V5: =IF(COUNT(S5:S7)<3,"",AVERAGE(S5:S7)) -> 1 | W5: =0.5*T5 + 0.3*U5 + 0.2*V5 -> 0.2 | X5: =S5 - W5 -> -0.2 | Y5: =ABS(S5 - W5) -> 0.2
A6: 179769 | B6: 46059 | C6: 1S19 | D6: 14:03 KINGS X to ABERDEEN | E6: YRK | F6: 4 | G6: 4 | H6: 43572 | I6: THBN | K6: New | N6: =IF(L6="Availability", 0, IF(AND(#REF!="Y", OR(F6>2,#REF!> 0)), 1, 0)) -> #REF! | S6: =_xlfn.XLOOKUP(E6,DelayData!C:C,DelayData!E:E,"0") -> 0 | T6: =S5 -> 0 | U6: =S4 -> 0 | V6: =IF(COUNT(S6:S8)<3,"",AVERAGE(S6:S8)) -> 1.6666667 | W6: =0.5*T6 + 0.3*U6 + 0.2*V6 -> 0.33333333 | X6: =S6 - W6 -> -0.33333333 | Y6: =ABS(S6 - W6) -> 0.33333333
A7: 177582 | B7: 46059 | C7: 5Y23 | D7: 21:22 KINGS X to BOUNDGNCS | E7: FERMEPK | F7: 44 | G7: 44 | H7: 43700 | I7: MHBJ | J7: MU | K7: Accepted | N7: =IF(L7="Availability", 0, IF(AND(#REF!="Y", OR(F7>2,#REF!> 0)), 1, 0)) -> #REF! | S7: =_xlfn.XLOOKUP(E7,DelayData!C:C,DelayData!E:E,"0") -> 3 | T7: =S6 -> 0 | U7: =S5 -> 0 | V7: =IF(COUNT(S7:S9)<3,"",AVERAGE(S7:S9)) -> 3 | W7: =0.5*T7 + 0.3*U7 + 0.2*V7 -> 0.6 | X7: =S7 - W7 -> 2.4 | Y7: =ABS(S7 - W7) -> 2.4
A8: 178518 | B8: 46059 | D8: 09:14 CRAIGNTNY to EDINBURGH | E8: XCN | F8: 5 | G8: 5 | H8: 43852 | I8: MHBK | K8: New | N8: =IF(L8="Availability", 0, IF(AND(#REF!="Y", OR(F8>2,#REF!> 0)), 1, 0)) -> #REF! | S8: =_xlfn.XLOOKUP(E8,DelayData!C:C,DelayData!E:E,"0") -> 2 | T8: =S7 -> 3 | U8: =S6 -> 0 | V8: =IF(COUNT(S8:S10)<3,"",AVERAGE(S8:S10)) -> 2 | W8: =0.5*T8 + 0.3*U8 + 0.2*V8 -> 1.9 | X8: =S8 - W8 -> 0.1 | Y8: =ABS(S8 - W8) -> 0.1
A9: 181387 | B9: 46060 | C9: 1A19 | D9: 11:37 Bradford Forster Square - Peterborough | E9: DON DONCLCJ | F9: 10 | G9: 17 | I9: MHBA | K9: New | N9: =IF(L9="Availability", 0, IF(AND(#REF!="Y", OR(F9>2,#REF!> 0)), 1, 0)) -> #REF! | S9: =_xlfn.XLOOKUP(E9,DelayData!C:C,DelayData!E:E,"0") -> 4 | T9: =S8 -> 2 | U9: =S7 -> 3 | V9: =IF(COUNT(S9:S11)<3,"",AVERAGE(S9:S11)) -> 10.333333 | W9: =0.5*T9 + 0.3*U9 + 0.2*V9 -> 3.9666667 | X9: =S9 - W9 -> 0.033333333 | Y9: =ABS(S9 - W9) -> 0.033333333
A10: 181742 | B10: 46060 | C10: 1S15 | D10: 12:03 KINGS X to INVERNES Running as 12:51 PETERBORO to INVERNES | E10: EDB | F10: 7 | G10: 14 | H10: 44013 | I10: THBN | K10: New | N10: =IF(L10="Availability", 0, IF(AND(#REF!="Y", OR(F10>2,#REF!> 0)), 1, 0)) -> #REF! | S10: =_xlfn.XLOOKUP(E10,DelayData!C:C,DelayData!E:E,"0") -> 0 | T10: =S9 -> 4 | U10: =S8 -> 2 | V10: =IF(COUNT(S10:S12)<3,"",AVERAGE(S10:S12)) -> 18 | W10: =0.5*T10 + 0.3*U10 + 0.2*V10 -> 6.2 | X10: =S10 - W10 -> -6.2 | Y10: =ABS(S10 - W10) -> 6.2
A11: 180998 | B11: 46060 | C11: 3S08 | D11: 08:55 NEVHILL D to YORK | E11: XNL | F11: 7 | G11: 16 | H11: 43864 | I11: MHBM | K11: New | N11: =IF(L11="Availability", 0, IF(AND(#REF!="Y", OR(F11>2,#REF!> 0)), 1, 0)) -> #REF! | S11: =_xlfn.XLOOKUP(E11,DelayData!C:C,DelayData!E:E,"0") -> 27 | T11: =S10 -> 0 | U11: =S9 -> 4 | V11: =IF(COUNT(S11:S13)<3,"",AVERAGE(S11:S13)) -> 18 | W11: =0.5*T11 + 0.3*U11 + 0.2*V11 -> 4.8 | X11: =S11 - W11 -> 22.2 | Y11: =ABS(S11 - W11) -> 22.2
A12: 180628 | B12: 46060 | E12: XNL | F12: 6 | G12: 6 | I12: MHBM | K12: New | N12: =IF(L12="Availability", 0, IF(AND(#REF!="Y", OR(F12>2,#REF!> 0)), 1, 0)) -> #REF! | S12: =_xlfn.XLOOKUP(E12,DelayData!C:C,DelayData!E:E,"0") -> 27 | T12: =S11 -> 27 | U12: =S10 -> 0 | V12: =IF(COUNT(S12:S14)<3,"",AVERAGE(S12:S14)) -> 9 | W12: =0.5*T12 + 0.3*U12 + 0.2*V12 -> 15.3 | X12: =S12 - W12 -> 11.7 | Y12: =ABS(S12 - W12) -> 11.7
A13: 183386 | B13: 46061 | C13: 1A27 | D13: 15:34 Bradford Foster Square - London Kings Cross | E13: WKF | F13: 2 | G13: 3 | I13: MHBA | K13: New | N13: =IF(L13="Availability", 0, IF(AND(#REF!="Y", OR(F13>2,#REF!> 0)), 1, 0)) -> #REF! | S13: =_xlfn.XLOOKUP(E13,DelayData!C:C,DelayData!E:E,"0") -> 0 | T13: =S12 -> 27 | U13: =S11 -> 27 | V13: =IF(COUNT(S13:S15)<3,"",AVERAGE(S13:S15)) -> 0.66666667 | W13: =0.5*T13 + 0.3*U13 + 0.2*V13 -> 21.733333 | X13: =S13 - W13 -> -21.733333 | Y13: =ABS(S13 - W13) -> 21.733333
A14: 182765 | B14: 46061 | C14: 1E07 | D14: 08:55 EDINBURGH to KINGS X Running as 08:55 EDINBURGH to YORK | E14: EDB | F14: 14 | G14: 30 | H14: 43908 | I14: THBQ | K14: New | N14: =IF(L14="Availability", 0, IF(AND(#REF!="Y", OR(F14>2,#REF!> 0)), 1, 0)) -> #REF! | S14: =_xlfn.XLOOKUP(E14,DelayData!C:C,DelayData!E:E,"0") -> 0 | T14: =S13 -> 0 | U14: =S12 -> 27 | V14: =IF(COUNT(S14:S16)<3,"",AVERAGE(S14:S16)) -> 0.66666667 | W14: =0.5*T14 + 0.3*U14 + 0.2*V14 -> 8.2333333 | X14: =S14 - W14 -> -8.2333333 | Y14: =ABS(S14 - W14) -> 8.2333333
A15: 183270 | B15: 46061 | C15: 5E22 | D15: 15:08 CRAIGNTNY to EDINBURGH | E15: XCN | F15: 24 | G15: 43 | H15: 43908 | I15: THBN | K15: New | N15: =IF(L15="Availability", 0, IF(AND(#REF!="Y", OR(F15>2,#REF!> 0)), 1, 0)) -> #REF! | S15: =_xlfn.XLOOKUP(E15,DelayData!C:C,DelayData!E:E,"0") -> 2 | T15: =S14 -> 0 | U15: =S13 -> 0 | V15: =IF(COUNT(S15:S17)<3,"",AVERAGE(S15:S17)) -> 0.66666667 | W15: =0.5*T15 + 0.3*U15 + 0.2*V15 -> 0.13333333 | X15: =S15 - W15 -> 1.8666667 | Y15: =ABS(S15 - W15) -> 1.8666667
A16: 184173 | B16: 46062 | C16: 1A02 | D16: 05:00 Leeds - London Kings Cross | E16: LDS | F16: 0 | G16: 16 | I16: MHBC | K16: New | N16: =IF(L16="Availability", 0, IF(AND(#REF!="Y", OR(F16>2,#REF!> 0)), 1, 0)) -> #REF! | S16: =_xlfn.XLOOKUP(E16,DelayData!C:C,DelayData!E:E,"0") -> 0 | T16: =S15 -> 2 | U16: =S14 -> 0 | V16: =IF(COUNT(S16:S18)<3,"",AVERAGE(S16:S18)) -> 0 | W16: =0.5*T16 + 0.3*U16 + 0.2*V16 -> 1 | X16: =S16 - W16 -> -1 | Y16: =ABS(S16 - W16) -> 1
A17: 184308 | B17: 46062 | C17: 1A07 | D17: 06:30 BRADFORSQ to KINGS X | E17: LDS | F17: 4 | G17: 4 | H17: 44005 | I17: MHB2 | K17: New | N17: =IF(L17="Availability", 0, IF(AND(#REF!="Y", OR(F17>2,#REF!> 0)), 1, 0)) -> #REF! | S17: =_xlfn.XLOOKUP(E17,DelayData!C:C,DelayData!E:E,"0") -> 0 | T17: =S16 -> 0 | U17: =S15 -> 2 | V17: =IF(COUNT(S17:S19)<3,"",AVERAGE(S17:S19)) -> 4 | W17: =0.5*T17 + 0.3*U17 + 0.2*V17 -> 1.4 | X17: =S17 - W17 -> -1.4 | Y17: =ABS(S17 - W17) -> 1.4
A18: 185048 | B18: 46062 | C18: 1B86 | D18: 12:47 KINGS X to LINCLNCEN | E18: KGX | F18: 15 | G18: 31 | H18: 43721 | I18: MHB1 | K18: New | N18: =IF(L18="Availability", 0, IF(AND(#REF!="Y", OR(F18>2,#REF!> 0)), 1, 0)) -> #REF! | S18: =_xlfn.XLOOKUP(E18,DelayData!C:C,DelayData!E:E,"0") -> 0 | T18: =S17 -> 0 | U18: =S16 -> 0 | V18: =IF(COUNT(S18:S20)<3,"",AVERAGE(S18:S20)) -> 5.3333333 | W18: =0.5*T18 + 0.3*U18 + 0.2*V18 -> 1.0666667 | X18: =S18 - W18 -> -1.0666667 | Y18: =ABS(S18 - W18) -> 1.0666667
A19: 185246 | B19: 46062 | C19: 1E16 | D19: 13:00 EDINBURGH to KINGS X | E19: NCL | F19: 14 | G19: 21 | H19: 43988 | I19: MHB2 | K19: New | N19: =IF(L19="Availability", 0, IF(AND(#REF!="Y", OR(F19>2,#REF!> 0)), 1, 0)) -> #REF! | S19: =_xlfn.XLOOKUP(E19,DelayData!C:C,DelayData!E:E,"0") -> 12 | T19: =S18 -> 0 | U19: =S17 -> 0 | V19: =IF(COUNT(S19:S21)<3,"",AVERAGE(S19:S21)) -> 5.3333333 | W19: =0.5*T19 + 0.3*U19 + 0.2*V19 -> 1.0666667 | X19: =S19 - W19 -> 10.933333 | Y19: =ABS(S19 - W19) -> 10.933333
A20: 185801 | B20: 46062 | C20: 1E17 | D20: 13:30 EDINBURGH to KINGS X | E20: DON DONCLCJ | F20: 2 | G20: 8 | H20: 43972 | I20: MHB2 | K20: New | N20: =IF(L20="Availability", 0, IF(AND(#REF!="Y", OR(F20>2,#REF!> 0)), 1, 0)) -> #REF! | S20: =_xlfn.XLOOKUP(E20,DelayData!C:C,DelayData!E:E,"0") -> 4 | T20: =S19 -> 12 | U20: =S18 -> 0 | V20: =IF(COUNT(S20:S22)<3,"",AVERAGE(S20:S22)) -> 5.6666667 | W20: =0.5*T20 + 0.3*U20 + 0.2*V20 -> 7.1333333 | X20: =S20 - W20 -> -3.1333333 | Y20: =ABS(S20 - W20) -> 3.1333333
A21: 184254 | B21: 46062 | C21: 1N01 | D21: 06:33 KINGS X to NCASTLCEN | E21: KGX | F21: 11 | G21: 11 | H21: 43943 | I21: MHB2 | K21: New | N21: =IF(L21="Availability", 0, IF(AND(#REF!="Y", OR(F21>2,#REF!> 0)), 1, 0)) -> #REF! | S21: =_xlfn.XLOOKUP(E21,DelayData!C:C,DelayData!E:E,"0") -> 0 | T21: =S20 -> 4 | U21: =S19 -> 12 | V21: =IF(COUNT(S21:S23)<3,"",AVERAGE(S21:S23)) -> 13.333333 | W21: =0.5*T21 + 0.3*U21 + 0.2*V21 -> 8.2666667 | X21: =S21 - W21 -> -8.2666667 | Y21: =ABS(S21 - W21) -> 8.2666667
A22: 184268 | B22: 46062 | C22: 1Y04 | D22: 05:27 NCASTLCEN to KINGS X | E22: SHFTHLJ TEMPLHJ | F22: 11 | G22: 11 | H22: 44077 | I22: MHB2 | K22: New | N22: =IF(L22="Availability", 0, IF(AND(#REF!="Y", OR(F22>2,#REF!> 0)), 1, 0)) -> #REF! | S22: =_xlfn.XLOOKUP(E22,DelayData!C:C,DelayData!E:E,"0") -> 13 | T22: =S21 -> 0 | U22: =S20 -> 4 | V22: =IF(COUNT(S22:S24)<3,"",AVERAGE(S22:S24)) -> 15.333333 | W22: =0.5*T22 + 0.3*U22 + 0.2*V22 -> 4.2666667 | X22: =S22 - W22 -> 8.7333333 | Y22: =ABS(S22 - W22) -> 8.7333333
A23: 184293 | B23: 46062 | C23: 3A11 | D23: 06:40 NEVHILL D to BRADFORSQ | E23: XNL | F23: 7 | G23: 7 | H23: 43700 | I23: MHBM | K23: New | N23: =IF(L23="Availability", 0, IF(AND(#REF!="Y", OR(F23>2,#REF!> 0)), 1, 0)) -> #REF! | S23: =_xlfn.XLOOKUP(E23,DelayData!C:C,DelayData!E:E,"0") -> 27 | T23: =S22 -> 13 | U23: =S21 -> 0 | V23: =IF(COUNT(S23:S25)<3,"",AVERAGE(S23:S25)) -> 11 | W23: =0.5*T23 + 0.3*U23 + 0.2*V23 -> 8.7 | X23: =S23 - W23 -> 18.3 | Y23: =ABS(S23 - W23) -> 18.3
A24: 186855 | B24: 46063 | C24: 1A05 | D24: 06:05 Leeds - London Kings Cross | E24: NNG | F24: 4 | G24: 32 | I24: MHBA | K24: New | N24: =IF(L24="Availability", 0, IF(AND(#REF!="Y", OR(F24>2,#REF!> 0)), 1, 0)) -> #REF! | S24: =_xlfn.XLOOKUP(E24,DelayData!C:C,DelayData!E:E,"0") -> 6 | T24: =S23 -> 27 | U24: =S22 -> 13 | V24: =IF(COUNT(S24:S26)<3,"",AVERAGE(S24:S26)) -> 2 | W24: =0.5*T24 + 0.3*U24 + 0.2*V24 -> 17.8 | X24: =S24 - W24 -> -11.8 | Y24: =ABS(S24 - W24) -> 11.8
A25: 187971 | B25: 46063 | C25: 1D20 | D25: 15:10 London Kings Cross - Leeds | E25: PBO | F25: 3 | G25: 11 | I25: MHBB | K25: New | N25: =IF(L25="Availability", 0, IF(AND(#REF!="Y", OR(F25>2,#REF!> 0)), 1, 0)) -> #REF! | S25: =_xlfn.XLOOKUP(E25,DelayData!C:C,DelayData!E:E,"0") -> 0 | T25: =S24 -> 6 | U25: =S23 -> 27 | V25: =IF(COUNT(S25:S27)<3,"",AVERAGE(S25:S27)) -> 0 | W25: =0.5*T25 + 0.3*U25 + 0.2*V25 -> 11.1 | X25: =S25 - W25 -> -11.1 | Y25: =ABS(S25 - W25) -> 11.1
A26: 188162 | B26: 46063 | C26: 1S19 | D26: 14:03 KINGS X to ABERDEEN | E26: DAR | F26: 7 | G26: 7 | H26: 43584 | I26: MHB1 | K26: New | N26: =IF(L26="Availability", 0, IF(AND(#REF!="Y", OR(F26>2,#REF!> 0)), 1, 0)) -> #REF! | S26: =_xlfn.XLOOKUP(E26,DelayData!C:C,DelayData!E:E,"0") -> 0 | T26: =S25 -> 0 | U26: =S24 -> 6 | V26: =IF(COUNT(S26:S28)<3,"",AVERAGE(S26:S28)) -> 1 | W26: =0.5*T26 + 0.3*U26 + 0.2*V26 -> 2 | X26: =S26 - W26 -> -2 | Y26: =ABS(S26 - W26) -> 2
A27: 187126 | B27: 46063 | C27: 3A12 | D27: 07:15 DONCARIEP to LEEDS | E27: LDS | F27: 0 | G27: 2 | H27: 44077 | I27: MHB1 | J27: MS | K27: Accepted | N27: =IF(L27="Availability", 0, IF(AND(#REF!="Y", OR(F27>2,#REF!> 0)), 1, 0)) -> #REF! | S27: =_xlfn.XLOOKUP(E27,DelayData!C:C,DelayData!E:E,"0") -> 0 | T27: =S26 -> 0 | U27: =S25 -> 0 | V27: =IF(COUNT(S27:S29)<3,"",AVERAGE(S27:S29)) -> 34.666667 | W27: =0.5*T27 + 0.3*U27 + 0.2*V27 -> 6.9333333 | X27: =S27 - W27 -> -6.9333333 | Y27: =ABS(S27 - W27) -> 6.9333333
A28: 190994 | B28: 46064 | C28: 1D26 | D28: 18:03 KINGS X to SKIPTON | E28: DON | F28: 11 | G28: 34 | H28: 43728 | I28: MHB2 | J28: M9 | K28: Accepted | N28: =IF(L28="Availability", 0, IF(AND(#REF!="Y", OR(F28>2,#REF!> 0)), 1, 0)) -> #REF! | S28: =_xlfn.XLOOKUP(E28,DelayData!C:C,DelayData!E:E,"0") -> 3 | T28: =S27 -> 0 | U28: =S26 -> 0 | V28: =IF(COUNT(S28:S30)<3,"0",AVERAGE(S28:S30)) -> 0 | W28: =0.5*T28 + 0.3*U28 + 0.2*V28 -> 0 | X28: =S28 - W28 -> 3 | Y28: =ABS(S28 - W28) -> 3
A29: 189004 | B29: 46064 | C29: 5Y26 | D29: 22:26 KINGS X to BOUNDGNCS | E29: BNDSGRN | F29: 33 | G29: 33 | H29: 43868 | I29: MHBJ | J29: MU | K29: Accepted | N29: =IF(L29="Availability", 0, IF(AND(#REF!="Y", OR(F29>2,#REF!> 0)), 1, 0)) -> #REF! | S29: =_xlfn.XLOOKUP(E29,DelayData!C:C,DelayData!E:E,"0") -> 101 | T29: =S28 -> 3 | U29: =S27 -> 0 | V29: =IF(COUNT(S29:S31)<3,"0",AVERAGE(S29:S31)) -> 0 | W29: =0.5*T29 + 0.3*U29 + 0.2*V29 -> 1.5 | X29: =S29 - W29 -> 99.5 | Y29: =ABS(S29 - W29) -> 99.5
A30: 192749 | B30: 46065 | C30: 1E15 | D30: 09:52 ABERDEEN to KINGS X | E30: EDB MNK | F30: 17 | G30: 83 | H30: 43550 | I30: MHB1 | K30: New | N30: =IF(L30="Availability", 0, IF(AND(#REF!="Y", OR(F30>2,#REF!> 0)), 1, 0)) -> #REF! | S30: =_xlfn.XLOOKUP(E30,DelayData!C:C,DelayData!E:E,"0") -> 0 | T30: =S29 -> 101 | U30: =S28 -> 3 | V30: 0 | W30: =0.5*T30 + 0.3*U30 + 0.2*V30 -> 51.4 | X30: =S30 - W30 -> -51.4 | Y30: =ABS(S30 - W30) -> 51.4
A31: 191716 | B31: 46065 | C31: 3Y03 | D31: 04:35 DONCARIEP to YORK Running as 04:57 DONCASTER to YORK | E31: DON | F31: 10 | G31: 21 | H31: 43819 | I31: MHB1 | K31: New | N31: =IF(L31="Availability", 0, IF(AND(#REF!="Y", OR(F31>2,#REF!> 0)), 1, 0)) -> #REF! | S31: =_xlfn.XLOOKUP(E31,DelayData!C:C,DelayData!E:E,"0") -> 3 | T31: =S30 -> 0 | U31: =S29 -> 101 | V31: =IF(COUNT(S31:S33)<3,"",AVERAGE(S31:S33)) -> 12 | W31: =0.5*T31 + 0.3*U31 + 0.2*V31 -> 32.7 | X31: =S31 - W31 -> -29.7 | Y31: =ABS(S31 - W31) -> 29.7
A32: 191778 | B32: 46065 | C32: 5A02 | E32: XNL | F32: 59 | G32: 143 | I32: MHBC | K32: New | N32: =IF(L32="Availability", 0, IF(AND(#REF!="Y", OR(F32>2,#REF!> 0)), 1, 0)) -> #REF! | S32: =_xlfn.XLOOKUP(E32,DelayData!C:C,DelayData!E:E,"0") -> 27 | T32: =S31 -> 3 | U32: =S30 -> 0 | V32: =IF(COUNT(S32:S34)<3,"",AVERAGE(S32:S34)) -> 11 | W32: =0.5*T32 + 0.3*U32 + 0.2*V32 -> 3.7 | X32: =S32 - W32 -> 23.3 | Y32: =ABS(S32 - W32) -> 23.3
A33: 192000 | B33: 46065 | C33: 5S08 | D33: 06:34 FERMEPARK to KINGS X | E33: FRMPKRS | F33: 5 | G33: 5 | I33: MHBJ | K33: New | N33: =IF(L33="Availability", 0, IF(AND(#REF!="Y", OR(F33>2,#REF!> 0)), 1, 0)) -> #REF! | S33: =_xlfn.XLOOKUP(E33,DelayData!C:C,DelayData!E:E,"0") -> 6 | T33: =S32 -> 27 | U33: =S31 -> 3 | V33: =IF(COUNT(S33:S35)<3,"",AVERAGE(S33:S35)) -> 2 | W33: =0.5*T33 + 0.3*U33 + 0.2*V33 -> 14.8 | X33: =S33 - W33 -> -8.8 | Y33: =ABS(S33 - W33) -> 8.8
A34: 176963 | B34: 46058 | C34: 1E25 | D34: 14:52 ABERDEEN to KINGS X | E34: KDY INK | F34: 2 | G34: 2 | H34: 43572 | I34: MHB1 | K34: New | N34: =IF(L34="Availability", 0, IF(AND(#REF!="Y", OR(F34>2,#REF!> 0)), 1, 0)) -> #REF! | S34: =_xlfn.XLOOKUP(E34,DelayData!C:C,DelayData!E:E,"Not Found") -> 0 | T34: =tbl_master[[#This Row],[Delay Mins]] -> 0 | U34: =S33 -> 6 | V34: {=IF(V5COUNT(S34:S36)<3,"",AVERAGE(S34:S36))} -> #NAME? | W34: =0.5*T34 + 0.3*U34 + 0.2*V34 -> #NAME? | X34: =S34 - W34 -> #NAME? | Y34: =ABS(S34 - W34) -> #NAME?
A35: 176917 | B35: 46058 | C35: 1S24 | D35: 16:30 KINGS X to EDINBURGH | E35: YRK | F35: 3 | G35: 3 | H35: 43791 | I35: RHBK | K35: New | N35: =IF(L35="Availability", 0, IF(AND(#REF!="Y", OR(F35>2,#REF!> 0)), 1, 0)) -> #REF! | S35: =_xlfn.XLOOKUP(E35,DelayData!C:C,DelayData!E:E,"Not Found") -> 0 | T35: =tbl_master[[#This Row],[Delay Mins]] -> 0 | U35: =S34 -> 0 | V35: {=IF(V5COUNT(S35:S37)<3,"",AVERAGE(S35:S37))} -> #NAME? | W35: =0.5*T35 + 0.3*U35 + 0.2*V35 -> #NAME? | X35: =S35 - W35 -> #NAME? | Y35: =ABS(S35 - W35) -> #NAME?
A36: 176008 | B36: 46058 | C36: 1S05 | D36: 07:03 KINGS X to EDINBURGH | E36: BELFORD BWK | F36: 4 | G36: 11 | H36: 43998 | I36: MHB2 | K36: New | N36: =IF(L36="Availability", 0, IF(AND(#REF!="Y", OR(F36>2,#REF!> 0)), 1, 0)) -> #REF! | S36: =_xlfn.XLOOKUP(E36,DelayData!C:C,DelayData!E:E,"Not Found") -> 0 | T36: =tbl_master[[#This Row],[Delay Mins]] -> 0 | U36: =S35 -> 0 | V36: {=IF(V5COUNT(S36:S38)<3,"",AVERAGE(S36:S38))} -> #NAME? | W36: =0.5*T36 + 0.3*U36 + 0.2*V36 -> #NAME? | X36: =S36 - W36 -> #NAME? | Y36: =ABS(S36 - W36) -> #NAME?
A37: 175515 | B37: 46058 | C37: 1S04 | D37: 06:30 KINGS X to EDINBURG | E37: NNG RET | F37: 6 | G37: 6 | H37: 43783 | I37: MHB2 | J37: M7 | K37: Accepted | N37: =IF(L37="Availability", 0, IF(AND(#REF!="Y", OR(F37>2,#REF!> 0)), 1, 0)) -> #REF! | S37: =_xlfn.XLOOKUP(E37,DelayData!C:C,DelayData!E:E,"Not Found") -> 0 | T37: =tbl_master[[#This Row],[Delay Mins]] -> 0 | U37: =S36 -> 0 | V37: {=IF(V5COUNT(S37:S39)<3,"",AVERAGE(S37:S39))} -> #NAME? | W37: =0.5*T37 + 0.3*U37 + 0.2*V37 -> #NAME? | X37: =S37 - W37 -> #NAME? | Y37: =ABS(S37 - W37) -> #NAME?
A38: 175190 | B38: 46058 | D38: 05:35 Neville Hill T&R.S.M.D - Leeds | E38: XNL | F38: 4 | G38: 4 | I38: MHBM | K38: New | N38: =IF(L38="Availability", 0, IF(AND(#REF!="Y", OR(F38>2,#REF!> 0)), 1, 0)) -> #REF! | S38: =_xlfn.XLOOKUP(E38,DelayData!C:C,DelayData!E:E,"Not Found") -> 27 | T38: =tbl_master[[#This Row],[Delay Mins]] -> 27 | U38: =S37 -> 0 | V38: {=IF(V5COUNT(S38:S40)<3,"",AVERAGE(S38:S40))} -> #NAME? | W38: =0.5*T38 + 0.3*U38 + 0.2*V38 -> #NAME? | X38: =S38 - W38 -> #NAME? | Y38: =ABS(S38 - W38) -> #NAME?
A39: 173841 | B39: 46057 | C39: 1A24 | D39: 14:40 Leeds - London Kings Cross | E39: AWK DON | F39: 14 | G39: 23 | I39: MHBA | J39: M1 | K39: Accepted | N39: =IF(L39="Availability", 0, IF(AND(#REF!="Y", OR(F39>2,#REF!> 0)), 1, 0)) -> #REF! | S39: =_xlfn.XLOOKUP(E39,DelayData!C:C,DelayData!E:E,"Not Found") -> 0 | T39: =tbl_master[[#This Row],[Delay Mins]] -> 0 | U39: =S38 -> 27 | V39: {=IF(V5COUNT(S39:S41)<3,"",AVERAGE(S39:S41))} -> #NAME? | W39: =0.5*T39 + 0.3*U39 + 0.2*V39 -> #NAME? | X39: =S39 - W39 -> #NAME? | Y39: =ABS(S39 - W39) -> #NAME?
A40: 172843 | B40: 46057 | C40: 3A13 | D40: 07:12 NEVHILL D to HARROGATE | E40: XNL | F40: 11 | G40: 11 | H40: 43920 | I40: MHBM | K40: New | N40: =IF(L40="Availability", 0, IF(AND(#REF!="Y", OR(F40>2,#REF!> 0)), 1, 0)) -> #REF! | S40: =_xlfn.XLOOKUP(E40,DelayData!C:C,DelayData!E:E,"Not Found") -> 27 | T40: =tbl_master[[#This Row],[Delay Mins]] -> 27 | U40: =S39 -> 0 | V40: {=IF(V5COUNT(S40:S42)<3,"",AVERAGE(S40:S42))} -> #NAME? | W40: =0.5*T40 + 0.3*U40 + 0.2*V40 -> #NAME? | X40: =S40 - W40 -> #NAME? | Y40: =ABS(S40 - W40) -> #NAME?
...

Sheet LOOKUPS
A1: LNER_Fleet_Status | B1: Who_Accepted | C1: Who_Referred | D1: Who_Requested | E1: Waiting_Att_Mgr_Decision | F1: Wtg_Referral_Dec | G1: Hitachi_Status | H1: Yes_No | I1: Vehicle_No | J1: Unit_No
A2: Investigation | B2: Fleet | C2: 225 Fleet Tech | D2: Driver | E2: Driver Error | F2: 225 Fleet Tech | G2: Investigation | H2: Y | I2: 811101 | J2: 800101
A3: Accepted | B3: Other | C3: TM | D3: TM | E3: TM Error | F3: TM | G3: Accepted | H3: N | I3: 811102 | J3: 800102
A4: Referred | B4: 225 Depot | C4: Driver | D4: Station | E4: Driver Door Obstacle | F4: Driver | G4: Availability | I4: 811103 | J4: 800103
A5: Report_Requested | C5: Station | D5: Onboard | E5: Passengers | F5: Station | G5: Merged | I5: 811104 | J5: 800104
A6: Merged with Master | C6: NR | D6: HRL | E6: Incorrect Dispatch | F6: NR | G6: TOC Dispute | I6: 811105 | J6: 800105
A7: Refer to Level 2 | C7: Control | D7: Ops | E7: Incident not Reported to MC | F7: Control | G7: Rejected - Class 3/5 | I7: 811106 | J7: 800106
A8: Wtg_Att_Mgr_Dec | C8: Other | D8: NR | E8: Awaiting Stoke Tech | F8: Other | G8: Rejected - Unsold Unit | I8: 811107 | J8: 800107
A9: Wtg_Referral_Dec | C9: Vandalism | E9: Awaiting CCF to Review | F9: Vandalism | G9: Rejected - Sub Threshold | I9: 811108 | J9: 800108
A10: Discuss with HRL | E10: Awaiting NR | F10: Awaiting DRV Report | G10: Rejected - 225 delay | I10: 811109 | J10: 800109
E11: Awaiting Amendment TRUST/Bugle Code | F11: Awaiting DTM to Review | G11: Rejected | I11: 811110 | J11: 800110
E12: Awaiting Attribution Decision | F12: Awaiting TM Report | I12: 811111 | J12: 800111
F13: Awaiting Referral Acceptance | I13: 811112 | J13: 800112
I14: 811113 | J14: 800113
I15: 812101 | J15: 800201
I16: 812102 | J16: 800202
I17: 812103 | J17: 800203
I18: 812104 | J18: 800204
I19: 812105 | J19: 800205
I20: 812106 | J20: 800206
I21: 812107 | J21: 800207
I22: 812108 | J22: 800208
I23: 812109 | J23: 800209
I24: 812110 | J24: 800210
I25: 812111 | J25: 801101
... I75: 816109 | J75: undefined
I76: 816110
I77: 816111
I78: 816112
I79: 816113
I80: 817101
I81: 817102
I82: 817103
I83: 817104
I84: 817105
I85: 817106
I86: 817107
I87: 817108
... I592: 91130

Sheet CODES
A1: Code | B1: System_SubSystem_Component | C1: Safety_Critical | D1: System_Code | E1: System | F1: SubSystem_Code | G1: SubSystem | H1: Component_Code | I1: Component | J1: Fleet
A2: 1A9 | B2: Operational_Staff_No Fault Identified | C2: N | D2: 1 | E2: Operational | F2: A | G2: Staff | H2: 9 | I2: No Fault Identified | J2: Azuma
A3: 1AA | B3: Operational_Staff_Driver | C3: N | D3: 1 | E3: Operational | F3: A | G3: Staff | H3: A | I3: Driver | J3: Azuma
A4: 1AB | B4: Operational_Staff_TM | C4: N | D4: 1 | E4: Operational | F4: A | G4: Staff | H4: B | I4: TM | J4: Azuma
A5: 1AC | B5: Operational_Staff_Train Crew | C5: N | D5: 1 | E5: Operational | F5: A | G5: Staff | H5: C | I5: Train Crew | J5: Azuma
A6: 1AD | B6: Operational_Staff_Platform | C6: N | D6: 1 | E6: Operational | F6: A | G6: Staff | H6: D | I6: Platform | J6: Azuma
A7: 1AE | B7: Operational_Staff_Other | C7: N | D7: 1 | E7: Operational | F7: A | G7: Staff | H7: E | I7: Other | J7: Azuma
A8: 1B9 | B8: Operational_Depot_No Fault Identified | C8: N | D8: 1 | E8: Operational | F8: B | G8: Depot | H8: 9 | I8: No Fault Identified | J8: Azuma
A9: 1BA | B9: Operational_Depot_InfraStructure | C9: N | D9: 1 | E9: Operational | F9: B | G9: Depot | H9: A | I9: InfraStructure | J9: Azuma
A10: 1BB | B10: Operational_Depot_Awaiting Acceptance | C10: N | D10: 1 | E10: Operational | F10: B | G10: Depot | H10: B | I10: Awaiting Acceptance | J10: Azuma
A11: 1BC | B11: Operational_Depot_Planning | C11: N | D11: 1 | E11: Operational | F11: B | G11: Depot | H11: C | I11: Planning | J11: Azuma
A12: 1BD | B12: Operational_Depot_Process | C12: N | D12: 1 | E12: Operational | F12: B | G12: Depot | H12: D | I12: Process | J12: Azuma
... A88: 225-2BN | B88: LNER_Other_Passenger Vandalism | C88: N | D88: 2 | E88: LNER | F88: B | G88: Other | H88: N | I88: Passenger Vandalism | J88: 225
A89: 225-AA1 | B89: Air System_Control_No Fault Identified | D89: A | E89: Air System | F89: A | G89: Control | H89: 1 | I89: No Fault Identified | J89: 225
A90: 225-AAA | B90: Air System_Control_Contactor Single phase | D90: A | E90: Air System | F90: A | G90: Control | H90: A | I90: Contactor Single phase | J90: 225
A91: 225-AAB | B91: Air System_Control_Contactor three phase | D91: A | E91: Air System | F91: A | G91: Control | H91: B | I91: Contactor three phase | J91: 225
A92: 225-AAC | B92: Air System_Control_Contactor - Change over | D92: A | E92: Air System | F92: A | G92: Control | H92: C | I92: Contactor - Change over | J92: 225
A93: 225-AAD | B93: Air System_Control_Contactor coil | D93: A | E93: Air System | F93: A | G93: Control | H93: D | I93: Contactor coil | J93: 225
A94: 225-AAE | B94: Air System_Control_Contactor fixed tip | D94: A | E94: Air System | F94: A | G94: Control | H94: E | I94: Contactor fixed tip | J94: 225
A95: 225-AAF | B95: Air System_Control_Contactor moving tip | D95: A | E95: Air System | F95: A | G95: Control | H95: F | I95: Contactor moving tip | J95: 225
A96: 225-AAG | B96: Air System_Control_Knuckle Spring | D96: A | E96: Air System | F96: A | G96: Control | H96: G | I96: Knuckle Spring | J96: 225
A97: 225-AAH | B97: Air System_Control_Terminal Connections | D97: A | E97: Air System | F97: A | G97: Control | H97: H | I97: Terminal Connections | J97: 225
A98: 225-AAI | B98: Air System_Control_Terminal fasteners | D98: A | E98: Air System | F98: A | G98: Control | H98: I | I98: Terminal fasteners | J98: 225
A99: 225-AAJ | B99: Air System_Control_Arc Chute | D99: A | E99: Air System | F99: A | G99: Control | H99: J | I99: Arc Chute | J99: 225
A100: 225-AAK | B100: Air System_Control_Wiring | D100: A | E100: Air System | F100: A | G100: Control | H100: K | I100: Wiring | J100: 225
... A2753: 225-ZFH | B2753: Equipment_Portable Fire_Fire Blanket (catering) | D2753: Z | E2753: Equipment | F2753: F | G2753: Portable Fire | H2753: H | I2753: Fire Blanket (catering) | J2753: 225
A2754: AA6 | B2754: Air System_Air Horn_Fault not Investigated | C2754: Y | D2754: A | E2754: Air System | F2754: A | G2754: Air Horn | H2754: 6 | I2754: Fault not Investigated | J2754: Azuma
A2755: AA7 | B2755: Air System_Air Horn_Non Technical | C2755: Y | D2755: A | E2755: Air System | F2755: A | G2755: Air Horn | H2755: 7 | I2755: Non Technical | J2755: Azuma
A2756: AA8 | B2756: Air System_Air Horn_Operator | C2756: Y | D2756: A | E2756: Air System | F2756: A | G2756: Air Horn | H2756: 8 | I2756: Operator | J2756: Azuma
A2757: AA9 | B2757: Air System_Air Horn_No Fault Identified | C2757: Y | D2757: A | E2757: Air System | F2757: A | G2757: Air Horn | H2757: 9 | I2757: No Fault Identified | J2757: Azuma
A2758: AAA | B2758: Air System_Air Horn_EP Valve | C2758: Y | D2758: A | E2758: Air System | F2758: A | G2758: Air Horn | H2758: A | I2758: EP Valve | J2758: Azuma
A2759: AAB | B2759: Air System_Air Horn_Horn | C2759: Y | D2759: A | E2759: Air System | F2759: A | G2759: Air Horn | H2759: B | I2759: Horn | J2759: Azuma
A2760: AAC | B2760: Air System_Air Horn_Horn Pressure Switch | C2760: Y | D2760: A | E2760: Air System | F2760: A | G2760: Air Horn | H2760: C | I2760: Horn Pressure Switch | J2760: Azuma
A2761: AAD | B2761: Air System_Air Horn_Lever Operated Horn Valve | C2761: Y | D2761: A | E2761: Air System | F2761: A | G2761: Air Horn | H2761: D | I2761: Lever Operated Horn Valve | J2761: Azuma
A2762: AAE | B2762: Air System_Air Horn_Pipework | C2762: Y | D2762: A | E2762: Air System | F2762: A | G2762: Air Horn | H2762: E | I2762: Pipework | J2762: Azuma
A2763: AAF | B2763: Air System_Air Horn_Regulator | C2763: Y | D2763: A | E2763: Air System | F2763: A | G2763: Air Horn | H2763: F | I2763: Regulator | J2763: Azuma
A2764: AAG | B2764: Air System_Air Horn_Thermostatic Junction Box | C2764: Y | D2764: A | E2764: Air System | F2764: A | G2764: Air Horn | H2764: G | I2764: Thermostatic Junction Box | J2764: Azuma
A2765: AAH | B2765: Air System_Air Horn_Adverse Weather | C2765: Y | D2765: A | E2765: Air System | F2765: A | G2765: Air Horn | H2765: H | I2765: Adverse Weather | J2765: Azuma
... A2870: BCC | B2870: Brake System_Cab & Vestibule Equipment_Brake Coding MCB | C2870: Y | D2870: B | E2870: Brake System | F2870: C | G2870: Cab & Vestibule Equipment | H2870: C | I2870: Brake Coding MCB | J2870: Azuma
A2871: C8 | B2871: Water and Toilet Systems_SST Toilet Door_Operator | C2871: N | E2871: Water and Toilet Systems | F2871: C | G2871: SST Toilet Door | H2871: 8 | I2871: Operator | J2871: Azuma
...

Sheet DelayData
A1: Inc.# | B1: Incident Date | C1: Incident Location | D1: Total Mins | E1: Delay Mins | G1: =SUM(#REF!) -> #REF!
A2: 480134220401 | B2: 44652 | C2: YRK | D2: 8 | E2: 0
A3: 485541220403 | B3: 44654 | C3: XCN | D3: 2 | E3: 2
A4: 485877220403 | B4: 44654 | C4: KGX | D4: 6 | E4: 0
A5: 487346220404 | B5: 44655 | C5: KGX | D5: 3 | E5: 3
A6: 488234220404 | B6: 44655 | C6: CRCRFTJ | D6: 324 | E6: 181
A7: 488367220404 | B7: 44655 | C7: COLTONJ YRK | D7: 8 | E7: 0
A8: 489450220405 | B8: 44656 | C8: NNG GRA | D8: 51 | E8: 25
A9: 489832220405 | B9: 44656 | C9: LDS | D9: 3 | E9: 0
A10: 490889220405 | B10: 44656 | C10: PBO | D10: 3 | E10: 0
A11: 491787220406 | B11: 44657 | C11: NCASTLCEN | D11: 0 | E11: 0
A12: 491892220406 | B12: 44657 | C12: WHRDJN | D12: 47 | E12: 39
A13: 492464220406 | B13: 44657 | C13: LCN | D13: 7 | E13: 0
... A2440: 944576241031 | B2440: 45596 | C2440: PMT FKG | D2440: 4 | E2440: 0
A2441: 944576241101 | B2441: 45597 | D2441: 3 | E2441: 0
A2442: 946690241101 | B2442: 45597 | C2442: NNG | D2442: 119 | E2442: 101
A2443: 946812241101 | B2443: 45597 | C2443: INV AVM | D2443: 2 | E2443: 0
A2444: 947050241101 | B2444: 45597 | C2444: PIT PTH | D2444: 2 | E2444: 0
A2445: 947084241101 | B2445: 45597 | C2445: SOKEJ GRA | D2445: 1 | E2445: 0
A2446: 947156241101 | B2446: 45597 | C2446: KDY INK | D2446: 1 | E2446: 0
A2447: 951005241102 | B2447: 45598 | C2447: BWK | D2447: 3 | E2447: 0
A2448: 951236241102 | B2448: 45598 | C2448: GRA NNG | D2448: 12 | E2448: 10.5
A2449: 952537241103 | B2449: 45599 | C2449: XNL | D2449: 5 | E2449: 5
A2450: 952556241103 | B2450: 45599 | C2450: DONCIEP | D2450: 4 | E2450: 0
A2451: 952576241103 | B2451: 45599 | C2451: YRK | D2451: 9 | E2451: 4
A2452: 952971241103 | B2452: 45599 | C2452: DON | D2452: 35 | E2452: 21
A2453: 953050241103 | B2453: 45599 | C2453: KGX | D2453: 72 | E2453: 39
... A3926: 168071260202 | B3926: 46055 | C3926: LEEDS | D3926: 0 | E3926: 0

Sheet Sheet1
A2: Incident Location | B2: Sum of Delay Mins
A3: 1D05 | B3: 3
A4: 1E07 | B4: 0
A5: 23464 | B5: 0
A6: 3A10 | B6: 0
A7: 5A04 | B7: 0
A8: AAP | B8: 0
A9: AAP BNDSGRN | B9: 0
A10: AAP FPK | B10: 36
A11: AAP GDH | B11: 9
A12: AAP PBR | B12: 0
A13: AAP XGD | B13: 0
A14: ABD | B14: 145
... A362: Grand Total | B362: 48224.5

Sheet Sheet2
A2: Incident Date | B2: Sum of Delay Mins
A3: 45404 | B3: 15
A4: 45405 | B4: 0
A5: 45406 | B5: 58
A6: 45407 | B6: 0
A7: 45408 | B7: 85
A8: 45409 | B8: 153
A9: 45410 | B9: 168
A10: 45411 | B10: 121
A11: 45412 | B11: 51
A12: 45413 | B12: 66
A13: 45414 | B13: 76
A14: 45415 | B14: 136
... A650: 46065 | B650: 36
A651: Grand Total | B651: 48224.5

Sheet Sheet3
A2: Root Cause | B2: Sum of Delay Mins
A3: IN | B3: 0
A4: M0 | B4: 1978
A5: M015 | B5: 10
A6: M019 | B6: 167
A7: M020 | B7: 3
A8: M034 | B8: 20
A9: M039 | B9: 48
A10: M0BC | B10: 0
A11: M1 | B11: 1853.5
A12: M2 | B12: 147
A13: M7 | B13: 5118
A14: M703 | B14: 230
... A84: Grand Total | B84: 48224.5
